<?xml version="1.0"?>
<robot name="demo_robot">

  <!-- ── Materials ─────────────────────────────────────────────── -->
  <material name="dark_grey">
    <color rgba="0.2 0.2 0.2 1.0"/>
  </material>
  <material name="light_grey">
    <color rgba="0.6 0.6 0.6 1.0"/>
  </material>
  <material name="blue">
    <color rgba="0.2 0.4 0.8 1.0"/>
  </material>
  <material name="black">
    <color rgba="0.05 0.05 0.05 1.0"/>
  </material>

  <!-- ── Base link (chassis) ────────────────────────────────────── -->
  <link name="base_link">
    <visual>
      <geometry>
        <box size="0.30 0.20 0.10"/>
      </geometry>
      <origin xyz="0 0 0.05" rpy="0 0 0"/>
      <material name="dark_grey"/>
    </visual>
    <collision>
      <geometry>
        <box size="0.30 0.20 0.10"/>
      </geometry>
      <origin xyz="0 0 0.05" rpy="0 0 0"/>
    </collision>
    <inertial>
      <mass value="5.0"/>
      <inertia ixx="0.05" ixy="0" ixz="0"
               iyy="0.06" iyz="0"
               izz="0.09"/>
    </inertial>
  </link>

  <!-- ── Left wheel ─────────────────────────────────────────────── -->
  <link name="left_wheel">
    <visual>
      <geometry>
        <cylinder radius="0.05" length="0.03"/>
      </geometry>
      <material name="black"/>
    </visual>
    <collision>
      <geometry>
        <cylinder radius="0.05" length="0.03"/>
      </geometry>
    </collision>
    <inertial>
      <mass value="0.5"/>
      <inertia ixx="0.001" ixy="0" ixz="0"
               iyy="0.001" iyz="0"
               izz="0.001"/>
    </inertial>
  </link>

  <joint name="left_wheel_joint" type="continuous">
    <parent link="base_link"/>
    <child  link="left_wheel"/>
    <origin xyz="0.0 0.115 0.05" rpy="-1.5708 0 0"/>
    <axis   xyz="0 0 1"/>
  </joint>

  <!-- ── Right wheel ────────────────────────────────────────────── -->
  <link name="right_wheel">
    <visual>
      <geometry>
        <cylinder radius="0.05" length="0.03"/>
      </geometry>
      <material name="black"/>
    </visual>
    <collision>
      <geometry>
        <cylinder radius="0.05" length="0.03"/>
      </geometry>
    </collision>
    <inertial>
      <mass value="0.5"/>
      <inertia ixx="0.001" ixy="0" ixz="0"
               iyy="0.001" iyz="0"
               izz="0.001"/>
    </inertial>
  </link>

  <joint name="right_wheel_joint" type="continuous">
    <parent link="base_link"/>
    <child  link="right_wheel"/>
    <origin xyz="0.0 -0.115 0.05" rpy="-1.5708 0 0"/>
    <axis   xyz="0 0 1"/>
  </joint>

  <!-- ── Caster (front passive wheel) ──────────────────────────── -->
  <link name="caster_link">
    <visual>
      <geometry>
        <sphere radius="0.025"/>
      </geometry>
      <material name="light_grey"/>
    </visual>
    <collision>
      <geometry>
        <sphere radius="0.025"/>
      </geometry>
    </collision>
    <inertial>
      <mass value="0.1"/>
      <inertia ixx="0.0001" ixy="0" ixz="0"
               iyy="0.0001" iyz="0"
               izz="0.0001"/>
    </inertial>
  </link>

  <joint name="caster_joint" type="fixed">
    <parent link="base_link"/>
    <child  link="caster_link"/>
    <origin xyz="0.13 0 0.025" rpy="0 0 0"/>
  </joint>

  <!-- ── Laser (LiDAR) ──────────────────────────────────────────── -->
  <link name="laser_link">
    <visual>
      <geometry>
        <cylinder radius="0.03" length="0.04"/>
      </geometry>
      <origin xyz="0 0 0.02" rpy="0 0 0"/>
      <material name="blue"/>
    </visual>
    <collision>
      <geometry>
        <cylinder radius="0.03" length="0.04"/>
      </geometry>
    </collision>
    <inertial>
      <mass value="0.2"/>
      <inertia ixx="0.0001" ixy="0" ixz="0"
               iyy="0.0001" iyz="0"
               izz="0.0001"/>
    </inertial>
  </link>

  <joint name="laser_joint" type="fixed">
    <parent link="base_link"/>
    <child  link="laser_link"/>
    <origin xyz="0.10 0 0.10" rpy="0 0 0"/>
  </joint>

  <!-- ── IMU link ───────────────────────────────────────────────── -->
  <link name="imu_link">
    <inertial>
      <mass value="0.01"/>
      <inertia ixx="1e-6" ixy="0" ixz="0"
               iyy="1e-6" iyz="0"
               izz="1e-6"/>
    </inertial>
  </link>

  <joint name="imu_joint" type="fixed">
    <parent link="base_link"/>
    <child  link="imu_link"/>
    <origin xyz="0 0 0.10" rpy="0 0 0"/>
  </joint>

  <!-- ── ROS2 Control / Gazebo tags ─────────────────────────────── -->
  <gazebo reference="base_link">
    <material>Gazebo/DarkGrey</material>
  </gazebo>
  <gazebo reference="left_wheel">
    <material>Gazebo/Black</material>
    <mu1>1.0</mu1>
    <mu2>1.0</mu2>
  </gazebo>
  <gazebo reference="right_wheel">
    <material>Gazebo/Black</material>
    <mu1>1.0</mu1>
    <mu2>1.0</mu2>
  </gazebo>

  <gazebo>
    <plugin name="diff_drive" filename="libgazebo_ros_diff_drive.so">
      <left_joint>left_wheel_joint</left_joint>
      <right_joint>right_wheel_joint</right_joint>
      <wheel_separation>0.23</wheel_separation>
      <wheel_diameter>0.10</wheel_diameter>
      <command_topic>cmd_vel</command_topic>
      <odometry_topic>odom</odometry_topic>
      <odometry_frame>odom</odometry_frame>
      <robot_base_frame>base_link</robot_base_frame>
    </plugin>
  </gazebo>

  <gazebo reference="laser_link">
    <sensor type="ray" name="laser">
      <pose>0 0 0 0 0 0</pose>
      <ray>
        <scan>
          <horizontal>
            <samples>360</samples>
            <resolution>1</resolution>
            <min_angle>-3.14159</min_angle>
            <max_angle>3.14159</max_angle>
          </horizontal>
        </scan>
        <range>
          <min>0.12</min>
          <max>3.5</max>
        </range>
      </ray>
      <plugin name="gazebo_ros_laser" filename="libgazebo_ros_ray_sensor.so">
        <ros>
          <remapping>~/out:=scan</remapping>
        </ros>
        <output_type>sensor_msgs/LaserScan</output_type>
        <frame_name>laser_link</frame_name>
      </plugin>
    </sensor>
  </gazebo>

</robot>
