<?xml version="1.0"?>
<robot name="diffbot">

  <!-- ── Links ──────────────────────────────────────────────────────────────── -->

  <link name="base_footprint"/>

  <link name="base_link">
    <visual>
      <geometry><box size="0.3 0.2 0.1"/></geometry>
      <origin xyz="0 0 0.05" rpy="0 0 0"/>
      <material name="dark_grey"><color rgba="0.2 0.2 0.2 1"/></material>
    </visual>
    <collision>
      <geometry><box size="0.3 0.2 0.1"/></geometry>
      <origin xyz="0 0 0.05" rpy="0 0 0"/>
    </collision>
    <inertial>
      <mass value="5.0"/>
      <inertia ixx="0.05" ixy="0" ixz="0" iyy="0.05" iyz="0" izz="0.05"/>
    </inertial>
  </link>

  <link name="left_wheel_link">
    <visual>
      <geometry><cylinder radius="0.065" length="0.04"/></geometry>
      <origin xyz="0 0 0" rpy="1.5707963 0 0"/>
      <material name="black"><color rgba="0.1 0.1 0.1 1"/></material>
    </visual>
    <collision>
      <geometry><cylinder radius="0.065" length="0.04"/></geometry>
      <origin xyz="0 0 0" rpy="1.5707963 0 0"/>
    </collision>
    <inertial>
      <mass value="0.5"/>
      <inertia ixx="0.001" ixy="0" ixz="0" iyy="0.001" iyz="0" izz="0.001"/>
    </inertial>
  </link>

  <link name="right_wheel_link">
    <visual>
      <geometry><cylinder radius="0.065" length="0.04"/></geometry>
      <origin xyz="0 0 0" rpy="1.5707963 0 0"/>
      <material name="black"/>
    </visual>
    <collision>
      <geometry><cylinder radius="0.065" length="0.04"/></geometry>
      <origin xyz="0 0 0" rpy="1.5707963 0 0"/>
    </collision>
    <inertial>
      <mass value="0.5"/>
      <inertia ixx="0.001" ixy="0" ixz="0" iyy="0.001" iyz="0" izz="0.001"/>
    </inertial>
  </link>

  <link name="caster_link">
    <visual>
      <geometry><sphere radius="0.025"/></geometry>
      <material name="grey"><color rgba="0.5 0.5 0.5 1"/></material>
    </visual>
    <collision>
      <geometry><sphere radius="0.025"/></geometry>
    </collision>
    <inertial>
      <mass value="0.1"/>
      <inertia ixx="0.0001" ixy="0" ixz="0" iyy="0.0001" iyz="0" izz="0.0001"/>
    </inertial>
  </link>

  <!-- ── Joints ─────────────────────────────────────────────────────────────── -->

  <joint name="base_footprint_joint" type="fixed">
    <parent link="base_footprint"/>
    <child  link="base_link"/>
    <origin xyz="0 0 0.065" rpy="0 0 0"/>
  </joint>

  <joint name="left_wheel_joint" type="continuous">
    <parent link="base_link"/>
    <child  link="left_wheel_link"/>
    <origin xyz="0.0 0.12 0" rpy="0 0 0"/>
    <axis xyz="0 1 0"/>
    <dynamics damping="0.01" friction="0.1"/>
  </joint>

  <joint name="right_wheel_joint" type="continuous">
    <parent link="base_link"/>
    <child  link="right_wheel_link"/>
    <origin xyz="0.0 -0.12 0" rpy="0 0 0"/>
    <axis xyz="0 1 0"/>
    <dynamics damping="0.01" friction="0.1"/>
  </joint>

  <joint name="caster_joint" type="fixed">
    <parent link="base_link"/>
    <child  link="caster_link"/>
    <origin xyz="-0.12 0 -0.04" rpy="0 0 0"/>
  </joint>

</robot>
